<?xml version="1.0"?>

<robot xmlns:xacro="http://www.ros.org/wiki/xacro"  name="crawler_description">

  <link
    name="base_link">
    <inertial>
      <origin
        xyz="-0.00703910246702688 -0.000837539533803048 0.010075447209685"
        rpy="0 0 0" />
      <mass
        value="21.7298438159499" />
      <inertia
        ixx="0.24800183576726"
        ixy="-3.57026723493335E-05"
        ixz="5.15090246517471E-05"
        iyy="0.508183725754325"
        iyz="0.000452422432613763"
        izz="0.70352937190044" />
    </inertial>
    <visual>
      <origin
        xyz="0 0 0.087"
        rpy="0 0 0" />
      <geometry>
        <mesh
          filename="package://crawler_description/meshes/base_link.STL" />
      </geometry>
      <material
        name="">
        <color
          rgba="0.792156862745098 0.819607843137255 0.933333333333333 1" />
      </material>
    </visual>
    <collision>
      <origin
        xyz="0 0 0.087"
        rpy="0 0 0" />
      <geometry>
        <mesh
          filename="package://crawler_description/meshes/base_link.STL" />
      </geometry>
    </collision>
  </link>
  <link
    name="font_lw">
    <inertial>
      <origin
        xyz="1.715E-05 -0.027 -3.1699E-05"
        rpy="0 0 0" />
      <mass
        value="0.8103" />
      <inertia
        ixx="0.0010675"
        ixy="-2.855E-19"
        ixz="-1.3622E-07"
        iyy="0.0017786"
        iyz="7.5478E-20"
        izz="0.0010676" />
    </inertial>
    <visual>
      <origin
        xyz="0 0 0.087"
        rpy="0 0 0" />
      <geometry>
        <mesh
          filename="package://crawler_description/meshes/font_lw.STL" />
      </geometry>
      <material
        name="">
        <color
          rgba="0.86667 0.9098 1 1" />
      </material>
    </visual>
    <collision>
      <origin
        xyz="0 0 0.087"
        rpy="0 0 0" />
      <geometry>
        <sphere radius="0.14982"/>
      </geometry>
    </collision>
  </link>
  <joint
    name="front_lj"
    type="continuous">
    <origin
      xyz="0.224 0.241 -0.025"
      rpy="0 0 0" />
    <parent
      link="base_link" />
    <child
      link="font_lw" />
    <axis
      xyz="0 1 0" />
    <limit
      lower="0"
      upper="0"
      effort="0"
      velocity="0" />
  </joint>
  <link
    name="front_rw">
    <inertial>
      <origin
        xyz="-8.31398520462212E-06 0.027 3.50687362817501E-05"
        rpy="0 0 0" />
      <mass
        value="0.810300971147523" />
      <inertia
        ixx="0.00106739400686659"
        ixy="1.62071139899744E-20"
        ixz="-7.30554873896416E-08"
        iyy="0.00177864343807052"
        iyz="2.04292838056139E-19"
        izz="0.00106768483819083" />
    </inertial>
    <visual>
      <origin
        xyz="0 0 0.087"
        rpy="0 0 0" />
      <geometry>
        <mesh
          filename="package://crawler_description/meshes/front_rw.STL" />
      </geometry>
      <material
        name="">
        <color
          rgba="0.866666666666667 0.909803921568627 1 1" />
      </material>
    </visual>
    <collision>
      <origin
        xyz="0 0 0.087"
        rpy="0 0 1.57" />
      <geometry>
        <sphere radius="0.14982"/>
      </geometry>
    </collision>
  </link>
  <joint
    name="front_rj"
    type="continuous">
    <origin
      xyz="0.224 -0.241 -0.025"
      rpy="0 0 0" />
    <parent
      link="base_link" />
    <child
      link="front_rw" />
    <axis
      xyz="0 -1 0" />
    <limit
      lower="0"
      upper="0"
      effort="0"
      velocity="0" />
  </joint>
  <link
    name="rear_lw">
    <inertial>
      <origin
        xyz="-1.51661689390403E-05 -0.027 -3.26944327690981E-05"
        rpy="0 0 0" />
      <mass
        value="0.810300971147523" />
      <inertia
        ixx="0.00106743432063593"
        ixy="-6.05051619617377E-20"
        ixz="1.24243354601579E-07"
        iyy="0.00177864343807052"
        iyz="-1.56291346747104E-19"
        izz="0.00106764452442149" />
    </inertial>
    <visual>
      <origin
        xyz="0 0 0.087"
        rpy="0 0 0" />
      <geometry>
        <mesh
          filename="package://crawler_description/meshes/rear_lw.STL" />
      </geometry>
      <material
        name="">
        <color
          rgba="0.866666666666667 0.909803921568627 1 1" />
      </material>
    </visual>
    <collision>
      <origin
        xyz="0 0 0.087"
        rpy="0 0 0" />
      <geometry>
        <sphere radius="0.14982"/>
      </geometry>
    </collision>
  </link>
  <joint
    name="rear_lj"
    type="continuous">
    <origin
      xyz="-0.224 0.241 -0.025"
      rpy="0 0 0" />
    <parent
      link="base_link" />
    <child
      link="rear_lw" />
    <axis
      xyz="0 1 0" />
    <limit
      lower="0"
      upper="0"
      effort="0"
      velocity="0" />
  </joint>
  <link
    name="rear_rw">
    <inertial>
      <origin
        xyz="-3.46892796005693E-05 0.027 9.77714146068592E-06"
        rpy="0 0 0" />
      <mass
        value="0.810300971147524" />
      <inertia
        ixx="0.00106767820565289"
        ixy="1.59097532244587E-19"
        ixz="-8.49827245494827E-08"
        iyy="0.00177864343807052"
        iyz="6.74123534685234E-20"
        izz="0.00106740063940453" />
    </inertial>
    <visual>
      <origin
        xyz="0 0 0.087"
        rpy="0 0 0" />
      <geometry>
        <mesh
          filename="package://crawler_description/meshes/rear_rw.STL" />
      </geometry>
      <material
        name="">
        <color
          rgba="0.866666666666667 0.909803921568627 1 1" />
      </material>
    </visual>
    <collision>
      <origin
        xyz="0 0 0.087"
        rpy="0 0 1.57" />
      <geometry>
        <sphere radius="0.14982"/>
      </geometry>
    </collision>
  </link>
  <joint
    name="rear_rj"
    type="continuous">
    <origin
      xyz="-0.224 -0.241 -0.025"
      rpy="0 0 0" />
    <parent
      link="base_link" />
    <child
      link="rear_rw" />
    <axis
      xyz="0 -1 0" />
    <limit
      lower="0"
      upper="0"
      effort="30"
      velocity="30" />
  </joint>
  <link
    name="lidar_link">
    <inertial>
      <origin
        xyz="3.53742851763594E-06 0.000115099330076087 -0.0233552371181321"
        rpy="0 0 0" />
      <mass
        value="0.10046205077288" />
      <inertia
        ixx="3.41937214679316E-05"
        ixy="2.13205778948088E-10"
        ixz="3.6291152025596E-10"
        iyy="3.42010786148691E-05"
        iyz="9.73147116595788E-09"
        izz="4.21147068405957E-05" />
    </inertial>
    <visual>
      <origin
        xyz="0 0 0.087"
        rpy="0 0 0" />
      <geometry>
        <mesh
          filename="package://crawler_description/meshes/lidar_link.STL" />
      </geometry>
      <material
        name="">
        <color
          rgba="0.792156862745098 0.819607843137255 0.933333333333333 1" />
      </material>
    </visual>
    <collision>
      <origin
        xyz="0 0 0.087"
        rpy="0 0 0" />
      <geometry>
        <mesh
          filename="package://crawler_description/meshes/lidar_link.STL" />
      </geometry>
    </collision>
  </link>
  <joint
    name="lidar_joint"
    type="fixed">
    <origin
      xyz="0.090667 0.00026794 0.1123"
      rpy="0 0 0" />
    <parent
      link="base_link" />
    <child
      link="lidar_link" />
    <axis
      xyz="0 0 0.087" />
  </joint>
  <link
    name="imu_link">
    <inertial>
      <origin
        xyz="1.72239381067262E-05 -1.86594203376725E-05 -0.000505961173496328"
        rpy="0 0 0" />
      <mass
        value="9.03345009183015E-06" />
      <inertia
        ixx="7.55386369994973E-12"
        ixy="-3.93145866833759E-14"
        ixz="1.52920786858737E-14"
        iyy="7.56016476574192E-12"
        iyz="-1.65665553526972E-14"
        izz="1.35874510536414E-11" />
    </inertial>
    <visual>
      <origin
        xyz="0 0 0.087"
        rpy="0 0 0" />
      <geometry>
        <mesh
          filename="package://crawler_description/meshes/imu_link.STL" />
      </geometry>
      <material
        name="">
        <color
          rgba="0.749019607843137 0.749019607843137 0.749019607843137 1" />
      </material>
    </visual>
    <collision>
      <origin
        xyz="0 0 0.087"
        rpy="0 0 0" />
      <geometry>
        <mesh
          filename="package://crawler_description/meshes/imu_link.STL" />
      </geometry>
    </collision>
  </link>
  <joint
    name="imu_joint"
    type="fixed">
    <origin
      xyz="-0.0088104 -0.0031329 0.07362"
      rpy="0 0 0" />
    <parent
      link="base_link" />
    <child
      link="imu_link" />
    <axis
      xyz="0 0 0.087" />
  </joint>
  <link
    name="left_belt_link">
    <inertial>
      <origin
        xyz="-1.38890281545954E-16 0.214 -0.025"
        rpy="0 0 0" />
      <mass
        value="0.195189817846963" />
      <inertia
        ixx="0.000726421753778775"
        ixy="3.8648287136937E-19"
        ixz="1.65519976716445E-18"
        iyy="0.00722882751707719"
        iyz="-3.41498357370188E-20"
        izz="0.00658373485406798" />
    </inertial>
    <visual>
      <origin
        xyz="0 0 0.0"
        rpy="0 0 0" />
      <geometry>
        <mesh
          filename="package://crawler_description/meshes/left_belt_link.STL" />
      </geometry>
      <material
        name="">
        <color
          rgba="0.298039215686275 0.298039215686275 0.298039215686275 1" />
      </material>
    </visual>
    <collision>
      <origin
        xyz="0 0 0.087"
        rpy="0 0 0" />
      <geometry>
        <mesh
          filename="package://crawler_description/meshes/left_belt_link.STL" />
      </geometry>
    </collision>
  </link>
  <joint
    name="left_belt_joint"
    type="fixed">
    <origin
      xyz="0 0 0.087"
      rpy="0 0 0" />
    <parent
      link="base_link" />
    <child
      link="left_belt_link" />
    <axis
      xyz="0 0 0.087" />
  </joint>
  <link
    name="right_belt_link">
    <inertial>
      <origin
        xyz="5.18128837727814E-16 -0.2145 -0.0249999999999989"
        rpy="0 0 0" />
      <mass
        value="0.222516392345537" />
      <inertia
        ixx="0.000842009530796705"
        ixy="2.44245500203075E-18"
        ixz="8.16412702478001E-18"
        iyy="0.00824086336946803"
        iyz="-3.0436798641957E-33"
        izz="0.00751934646512643" />
    </inertial>
    <visual>
      <origin
        xyz="0 0 0.087"
        rpy="0 0 0" />
      <geometry>
        <mesh
          filename="package://crawler_description/meshes/right_belt_link.STL" />
      </geometry>
      <material
        name="">
        <color
          rgba="0.298039215686275 0.298039215686275 0.298039215686275 1" />
      </material>
    </visual>
    <collision>
      <origin
        xyz="0 0 0.0"
        rpy="0 0 0" />
      <geometry>
        <mesh
          filename="package://crawler_description/meshes/right_belt_link.STL" />
      </geometry>
    </collision>
  </link>
  <joint
    name="right_belt_joint"
    type="fixed">
    <origin
      xyz="0 0 0.0"
      rpy="0 0 0" />
    <parent
      link="base_link" />
    <child
      link="right_belt_link" />
    <axis
      xyz="0 0 0.087" />
  </joint>
  <link
    name="realsense_link">
    <inertial>
      <origin
        xyz="-0.000562499999999966 -0.000501072127407474 1.24505187286406E-06"
        rpy="0 0 0" />
      <mass
        value="3.69692626267955E-05" />
      <inertia
        ixx="3.80548758633584E-08"
        ixy="-6.09327055012708E-24"
        ixz="2.59345743460586E-26"
        iyy="1.22919470785899E-09"
        iyz="8.84498420989037E-11"
        izz="3.68256850064643E-08" />
    </inertial>
    <visual>
      <origin
        xyz="0 0 0.087"
        rpy="0 0 0" />
      <geometry>
        <mesh
          filename="package://crawler_description/meshes/realsense_link.STL" />
      </geometry>
      <material
        name="">
        <color
          rgba="0.792156862745098 0.819607843137255 0.933333333333333 1" />
      </material>
    </visual>
    <collision>
      <origin
        xyz="0 0 0.087"
        rpy="0 0 0" />
      <geometry>
        <mesh
          filename="package://crawler_description/meshes/realsense_link.STL" />
      </geometry>
    </collision>
  </link>
  <joint
    name="realsense_j"
    type="fixed">
    <origin
      xyz="0.27754 0.00088472 0.037078"
      rpy="0 0 0" />
    <parent
      link="base_link" />
    <child
      link="realsense_link" />
    <axis
      xyz="0 0 0.087" />
  </joint>
</robot>